<?xml version="1.0"?>
<robot name="kuka_kr300_r2500">
  <link name="base_link"/>

  <!-- Joint 1 -->
  <joint name="joint_1" type="revolute">
    <parent link="base_link"/>
    <child link="link_1"/>
    <origin xyz="0 0 -0.675" rpy="0 0 0"/>
    <axis xyz="0 0 1"/>
    <limit lower="-3.14" upper="3.14" effort="200" velocity="1.0"/>
  </joint>
  <link name="link_1">
    <inertial>
      <mass value="1.0"/>
      <origin xyz="0.1 0.1 0.1" rpy="0 0 0"/>
      <inertia ixx="20" ixy="20" ixz="20" iyy="20" iyz="20" izz="20"/>
    </inertial>
  </link>

  <!-- Joint 2 -->
  <joint name="joint_2" type="revolute">
    <parent link="link_1"/>
    <child link="link_2"/>
    <origin xyz="0.35 0 0" rpy="1.5708 0 0"/>
    <axis xyz="0 0 1"/>
    <limit lower="-3.14" upper="3.14" effort="200" velocity="1.0"/>
  </joint>
  <link name="link_2">
    <inertial>
      <mass value="1.0"/>
      <origin xyz="0.1 0.1 0.1" rpy="0 0 0"/>
      <inertia ixx="20" ixy="20" ixz="20" iyy="20" iyz="20" izz="20"/>
    </inertial>
  </link>

  <!-- Joint 3 -->
  <joint name="joint_3" type="revolute">
    <parent link="link_2"/>
    <child link="link_3"/>
    <origin xyz="1.15 0 0" rpy="0 0 0"/>
    <axis xyz="0 0 1"/>
    <limit lower="-3.14" upper="3.14" effort="200" velocity="1.0"/>
  </joint>
  <link name="link_3">
    <inertial>
      <mass value="1.0"/>
      <origin xyz="0.1 0.1 0.1" rpy="0 0 0"/>
      <inertia ixx="20" ixy="20" ixz="20" iyy="20" iyz="20" izz="20"/>
    </inertial>
  </link>

  <!-- Joint 4 -->
  <joint name="joint_4" type="revolute">
    <parent link="link_3"/>
    <child link="link_4"/>
    <origin xyz="-0.041 0 -1.0" rpy="1.5708 0 0"/>
    <axis xyz="0 0 1"/>
    <limit lower="-3.14" upper="3.14" effort="200" velocity="1.0"/>
  </joint>
  <link name="link_4">
    <inertial>
      <mass value="1.0"/>
      <origin xyz="0.1 0.1 0.1" rpy="0 0 0"/>
      <inertia ixx="20" ixy="20" ixz="20" iyy="20" iyz="20" izz="20"/>
    </inertial>
  </link>

  <!-- Joint 5 -->
  <joint name="joint_5" type="revolute">
    <parent link="link_4"/>
    <child link="link_5"/>
    <origin xyz="0 0 0" rpy="-1.5708 0 0"/>
    <axis xyz="0 0 1"/>
    <limit lower="-3.14" upper="3.14" effort="200" velocity="1.0"/>
  </joint>
  <link name="link_5">
    <inertial>
      <mass value="1.0"/>
      <origin xyz="0.1 0.1 0.1" rpy="0 0 0"/>
      <inertia ixx="20" ixy="20" ixz="20" iyy="20" iyz="20" izz="20"/>
    </inertial>
  </link>

  <!-- Joint 6 -->
  <joint name="joint_6" type="revolute">
    <parent link="link_5"/>
    <child link="link_6"/>
    <origin xyz="0 0 0" rpy="1.5708 0 0"/>
    <axis xyz="0 0 1"/>
    <limit lower="-3.14" upper="3.14" effort="200" velocity="1.0"/>
  </joint>
  <link name="link_6">
    <inertial>
      <mass value="1.0"/>
      <origin xyz="0.1 0.1 0.1" rpy="0 0 0"/>
      <inertia ixx="20" ixy="20" ixz="20" iyy="20" iyz="20" izz="20"/>
    </inertial>
  </link>
</robot>
